Workbook

Sheet Feb_0_activation_date
A1: msisdn_key | B1: activation_date | C1: sorb_activation_date | F1: select msisdn_key, activation_date, sorb_activation_date from bsl.customersubject where aggr = 'monthly' and status in ('active') and payment_option = 'PREPAID' and tbl_dt = 20210228 and length(cast(activation_date as VARCHAR))<> 8
A2: 27,710,885,476 | B2: 0 | C2: 0
A3: 27,710,891,126 | B3: 0 | C3: 0
A4: 27,634,748,433 | B4: 0 | C4: 0
A5: 27,783,378,678 | B5: 0 | C5: 0
A6: 27,782,073,284 | B6: 0 | C6: 0
A7: 27,784,848,308 | B7: 0 | C7: 0
A8: 27,735,330,272 | B8: 0 | C8: 0
A9: 27,781,910,315 | B9: 0 | C9: 0
A10: 27,719,032,309 | B10: 0 | C10: 0
A11: 27,734,346,335 | B11: 0 | C11: 0
A12: 27,737,880,672 | B12: 0 | C12: 0
A13: 27,782,201,117 | B13: 0 | C13: 0
... A22: 27,735,718,802 | B22: 0 | C22: 0
A23: 27,786,923,091 | B23: 0 | C23: 0 | F23: select tbl_dt, COUNT(MSISDN) from bsl.customersubject where aggr = 'monthly' and status in ('active') --and payment_option = 'PREPAID' AND subscriber_type=1 AND customer_type = 'CONSUMER' and tbl_dt = 20210228 and length(cast(activation_date as VARCHAR))<> 8 group by tbl_dt
A24: 27,781,011,996 | B24: 0 | C24: 0
A25: 27,839,498,366 | B25: 0 | C25: 0
A26: 27,719,892,486 | B26: 0 | C26: 0
A27: 27,780,205,034 | B27: 0 | C27: 0
A28: 27,730,335,873 | B28: 0 | C28: 0
A29: 27,731,915,023 | B29: 0 | C29: 0
A30: 27,710,216,472 | B30: 0 | C30: 0
A31: 27,787,258,563 | B31: 0 | C31: 0
A32: 27,781,792,201 | B32: 0 | C32: 0
A33: 27,787,650,883 | B33: 0 | C33: 0
A34: 27,731,095,710 | B34: 0 | C34: 0
A35: 27,730,257,518 | B35: 0 | C35: 0
... A139: 27,780,871,091 | B139: 0 | C139: 0

Sheet Funnel
A1: OVERALL_BASE | B1: CONSUMER_BASE | C1: PREPAID_CONSUMER_BASE | D1: PREPAID_ACTIVE_CONSUMER_BASE
A2: 41,512,699 | B2: 35,301,753 | C2: 33,270,868 | D2: 24,998,823
A3: =A2/1000000 -> 41.512699 | B3: =B2/1000000 -> 35.301753 | C3: =C2/1000000 -> 33.270868 | D3: =D2/1000000 -> 24.998823
A4: customer_type = 'CONSUMER' | B4: subscriber_type = 1 | C4: status = 'active'
A8: ----------Funnel--------- --OVERALL_BASE_FEB1st select COUNT(MSISDN_KEY) as OVERALL_BASE from bsl.customersubject where tbl_dt = 20210201 and aggr = 'daily' --CONSUMER_OVERALL_BASE_FEB1st select COUNT(MSISDN_KEY) as CONSUMER_BASE from bsl.customersubject where tbl_dt = 20210201 and aggr = 'daily' --AND subscriber_type=1 and customer_type = 'CONSUMER' --PREPAID_CONSUMER_BASE_FEB1st select COUNT(MSISDN_KEY) as PREPAID_CONSUMER_BASE from bsl.customersubject where tbl_dt = 20210201 and aggr = 'daily' and subscriber_type = 1 and customer_type = 'CONSUMER' --PREPAID_ACTIVE_CONSUMER_BASE_FEB1st select COUNT(MSISDN_KEY) as PREPAID_ACTIVE_CONSUMER_BASE from bsl.customersubject where tbl_dt = 20210201 and aggr = 'daily' and subscriber_type = 1 and customer_type = 'CONSUMER' and status = 'active' and length(cast(activation_date as VARCHAR)) = 8

Sheet NEW
A1: DATE | B1: BASE_CNT | C1: SEG_CNT | D1: AON_SLAB | E1: ARPU_SLAB_IND | F1: Smartphone | G1: DataUser | H1: AVGL3MREV | I1: L1MR | J1: L2MR | K1: L3MR | L1: L1MR_ARPU | M1: L2MR_ARPU | N1: L3MR_ARPU | O1: Voice_Revenue | P1: Data_revenue | Q1: OG_MOU | R1: IC_MOU | S1: TOTAL_DATA_USAGE_MB | T1: CNT_DOLA_7INC | U1: CNT_DOLA_15INC | V1: CNT_DOLA_30INC | W1: CNT_DOLA_60INC | X1: CNT_DOLA_90INC
A2: 44228 | B2: 24998823 | D2: 0 - 3 months | E2: 0 - 10 ARPU | F2: 0 | G2: 0 | H2: 7722060.575461756 | I2: 13288873.143876359 | J2: 6501996.014662305 | K2: 3375312.5678735697 | L2: 4.02021992494238 | M2: 1.9670180945392388 | N2: 1.0211173431606357 | O2: 7029842.739994286 | P2: 3357101.6000009123 | Q2: 8381050 | R2: 16598795 | S2: 1024369032.5074024 | T2: 2374613 | U2: 2164288 | V2: 2003728 | W2: 1419706 | X2: 770951
A3: 44228 | B3: 24998823 | D3: 0 - 3 months | E3: 10 - 25 ARPU | F3: 0 | G3: 0 | H3: 17434475.825869404 | I3: 29233559.42906058 | J3: 15194447.564633075 | K3: 7875420.483930377 | L3: 24.695887641952872 | M3: 12.835945302805067 | N3: 6.652987292780333 | O3: 12017721.530002583 | P3: 8628754.230900299 | Q3: 16673168 | R3: 20410798 | S3: 680126355.4481382 | T3: 640519 | U3: 584395 | V3: 549121 | W3: 404751 | X3: 223102
A4: 44228 | B4: 24998823 | D4: 0 - 3 months | E4: 100 - 125 ARPU | F4: 0 | G4: 0 | H4: 7197556.786477435 | I4: 11626685.024083447 | J4: 7296940.236191129 | K4: 2669045.099157883 | L4: 179.95178802172182 | M4: 112.93824850938135 | N4: 41.31009285184775 | O4: 4573523.65999996 | P4: 4066469.850000022 | Q4: 7071441 | R4: 6097574 | S4: 197036602.45180893 | T4: 10753 | U4: 9404 | V4: 8563 | W4: 7329 | X4: 4424
A5: 44228 | B5: 24998823 | D5: 0 - 3 months | E5: 125 - 150 ARPU | F5: 0 | G5: 0 | H5: 5570106.507248575 | I5: 8886996.922199637 | J5: 5704191.189532798 | K5: 2119131.410013368 | L5: 217.9414111435279 | M5: 139.88746571677166 | N5: 51.96879147591456 | O5: 3421065.549999983 | P5: 3235683.4500000062 | Q5: 5254319 | R5: 4330380 | S5: 147590106.979043 | T5: 6313 | U5: 5561 | V5: 5070 | W5: 4328 | X5: 2598
A6: 44228 | B6: 24998823 | D6: 0 - 3 months | E6: 150 - 200 ARPU | F6: 0 | G6: 0 | H6: 7729045.240010807 | I6: 12197508.441815477 | J6: 8020110.944868887 | K6: 2969516.3333480866 | L6: 270.989501273366 | M6: 178.18113227586338 | N6: 65.97312508826924 | O6: 4550425.489999975 | P6: 4656805.730000006 | Q6: 6849945 | R6: 5403248 | S6: 203477860.18056297 | T6: 6282 | U6: 5566 | V6: 5046 | W6: 4331 | X6: 2619
A7: 44228 | B7: 24998823 | D7: 0 - 3 months | E7: 200 - 300 ARPU | F7: 0 | G7: 0 | H7: 8433758.434176952 | I7: 13039557.389473453 | J7: 8867437.991783824 | K7: 3394279.921273674 | L7: 371.9954751226272 | M7: 252.97229885555655 | N7: 96.83279380577052 | O7: 4832081.209999981 | P7: 5290285.910900011 | Q7: 6884552 | R7: 5222454 | S7: 205356855.01181412 | T7: 4227 | U7: 3797 | V7: 3448 | W7: 3029 | X7: 1809
A8: 44228 | B8: 24998823 | D8: 0 - 3 months | E8: 25 - 50 ARPU | F8: 0 | G8: 0 | H8: 19228946.653816707 | I8: 33903011.16800365 | J8: 17306437.094691053 | K8: 6477391.698758719 | L8: 62.39787381657694 | M8: 31.852181881360803 | N8: 11.92152130313235 | O8: 14696575.21000209 | P8: 10910009.291799681 | Q8: 20683127 | R8: 23311441 | S8: 625877088.9541445 | T8: 156754 | U8: 132691 | V8: 118857 | W8: 96080 | X8: 55805
A9: 44228 | B9: 24998823 | D9: 0 - 3 months | E9: 300 - 500 ARPU | F9: 0 | G9: 0 | H9: 6979374.354625089 | I9: 10486324.328720557 | J9: 7506629.527181095 | K9: 2945169.2079736646 | L9: 561.9379630631025 | M9: 402.26298307599245 | N9: 157.8248329657395 | O9: 3753827.0600000005 | P9: 4707854.460000003 | Q9: 4939253 | R9: 3814994 | S9: 150898980.45719814 | T9: 1794 | U9: 1632 | V9: 1500 | W9: 1322 | X9: 852
A10: 44228 | B10: 24998823 | D10: 0 - 3 months | E10: 50 - 75 ARPU | F10: 0 | G10: 0 | H10: 13820003.23482102 | I10: 23473532.92598217 | J10: 13189992.250890959 | K10: 4796484.527590749 | L10: 103.50886296722861 | M10: 58.16257419542883 | N10: 21.15057248759028 | O10: 9645476.009999897 | P10: 7829878.391800098 | Q10: 14357180 | R10: 14373727 | S10: 415580481.01681614 | T10: 50487 | U10: 43431 | V10: 39153 | W10: 32589 | X10: 19232
A11: 44228 | B11: 24998823 | D11: 0 - 3 months | E11: 75 - 100 ARPU | F11: 0 | G11: 0 | H11: 9894306.525161508 | I11: 16286878.86858612 | J11: 9794714.913244018 | K11: 3601325.7936546723 | L11: 141.90514205070983 | M11: 85.33988754536361 | N11: 31.37781354198873 | O11: 6541965.709999873 | P11: 5614148.530000046 | Q11: 9879655 | R11: 9017273 | S11: 275030474.1243839 | T11: 21683 | U11: 18773 | V11: 16936 | W11: 14160 | X11: 8462
A12: 44228 | B12: 24998823 | D12: 0 - 3 months | E12: GT 500 | F12: 0 | G12: 0 | H12: 6387649.051058449 | I12: 9048940.138456617 | J12: 7042143.339148301 | K12: 3071863.675570448 | L12: 1132.9585749914381 | M12: 881.7006810001628 | N12: 384.60794736076724 | O12: 2846476.7799999993 | P12: 4715441.870000001 | Q12: 3099015 | R12: 2351614 | S12: 122423838.77688217 | T12: 669 | U12: 609 | V12: 539 | W12: 451 | X12: 274
A13: 44228 | B13: 24998823 | D13: 0 - 3 months | E13: Zero or LT Zero ARPU | F13: 0 | G13: 0 | H13: -125005.78189164707 | I13: -182304.31944256497 | J13: -102566.01360449768 | K13: -90147.01262788152 | L13: -1.596010675793959 | M13: -0.8979296441628162 | N13: -0.7892056259827666 | O13: 46717.53999999981 | P13: 10047.290000000005 | Q13: 215141 | R13: 149968 | S13: 889549782.1098757 | T13: 43905 | U13: 40752 | V13: 38103 | W13: 28696 | X13: 19674
A15: 44228 | B15: 24998823 | D15: 0 - 3 months | E15: 0 - 10 ARPU | F15: 1 | G15: 0
A16: 44228 | B16: 24998823 | D16: 0 - 3 months | E16: 10 - 25 ARPU | F16: 1 | G16: 0
A17: 44228 | B17: 24998823 | D17: 0 - 3 months | E17: 100 - 125 ARPU | F17: 1 | G17: 0
A18: 44228 | B18: 24998823 | D18: 0 - 3 months | E18: 125 - 150 ARPU | F18: 1 | G18: 0
A19: 44228 | B19: 24998823 | D19: 0 - 3 months | E19: 150 - 200 ARPU | F19: 1 | G19: 0
A20: 44228 | B20: 24998823 | D20: 0 - 3 months | E20: 200 - 300 ARPU | F20: 1 | G20: 0
A21: 44228 | B21: 24998823 | D21: 0 - 3 months | E21: 25 - 50 ARPU | F21: 1 | G21: 0
A22: 44228 | B22: 24998823 | D22: 0 - 3 months | E22: 300 - 500 ARPU | F22: 1 | G22: 0
A23: 44228 | B23: 24998823 | D23: 0 - 3 months | E23: 50 - 75 ARPU | F23: 1 | G23: 0
A24: 44228 | B24: 24998823 | D24: 0 - 3 months | E24: 75 - 100 ARPU | F24: 1 | G24: 0
A25: 44228 | B25: 24998823 | D25: 0 - 3 months | E25: GT 500 | F25: 1 | G25: 0
A26: 44228 | B26: 24998823 | D26: 0 - 3 months | E26: Zero or LT Zero ARPU | F26: 1 | G26: 0
... A52: 44228 | B52: 24998823 | D52: 0 - 3 months | E52: Zero or LT Zero ARPU | F52: 1 | G52: 1

Sheet February
A1: DATE | B1: BASE_CNT | C1: SEG_CNT | D1: AON_SLAB | E1: ARPU_SLAB_IND | F1: AVGL3MREV | G1: L1MR | H1: L2MR | I1: L3MR | J1: L1MR_ARPU | K1: L2MR_ARPU | L1: L3MR_ARPU | M1: Voice_Revenue | N1: Data_revenue | O1: OG_MOU | P1: IC_MOU | Q1: TOTAL_DATA_USAGE_MB | R1: CNT_DOLA_7INC | S1: CNT_DOLA_15INC | T1: CNT_DOLA_30INC | U1: CNT_DOLA_60INC | V1: CNT_DOLA_90INC
A2: 44228 | B2: 24998823 | C2: 3305509 | D2: 0 - 3 months | E2: 0 - 10 ARPU | F2: 7722060.575461756 | G2: 13288873.143876359 | H2: 6501996.014662305 | I2: 3375312.5678735697 | J2: 4.02021992494238 | K2: 1.9670180945392388 | L2: 1.0211173431606357 | M2: 7029842.739994286 | N2: 3357101.6000009123 | O2: 8381050 | P2: 16598795 | Q2: 1024369032.5074024 | R2: 2374613 | S2: 2164288 | T2: 2003728 | U2: 1419706 | V2: 770951
A3: 44228 | B3: 24998823 | C3: 1183742 | D3: 0 - 3 months | E3: 10 - 25 ARPU | F3: 17434475.825869404 | G3: 29233559.42906058 | H3: 15194447.564633075 | I3: 7875420.483930377 | J3: 24.695887641952872 | K3: 12.835945302805067 | L3: 6.652987292780333 | M3: 12017721.530002583 | N3: 8628754.230900299 | O3: 16673168 | P3: 20410798 | Q3: 680126355.4481382 | R3: 640519 | S3: 584395 | T3: 549121 | U3: 404751 | V3: 223102
A4: 44228 | B4: 24998823 | C4: 64610 | D4: 0 - 3 months | E4: 100 - 125 ARPU | F4: 7197556.786477435 | G4: 11626685.024083447 | H4: 7296940.236191129 | I4: 2669045.099157883 | J4: 179.95178802172182 | K4: 112.93824850938135 | L4: 41.31009285184775 | M4: 4573523.65999996 | N4: 4066469.850000022 | O4: 7071441 | P4: 6097574 | Q4: 197036602.45180893 | R4: 10753 | S4: 9404 | T4: 8563 | U4: 7329 | V4: 4424
A5: 44228 | B5: 24998823 | C5: 40777 | D5: 0 - 3 months | E5: 125 - 150 ARPU | F5: 5570106.507248575 | G5: 8886996.922199637 | H5: 5704191.189532798 | I5: 2119131.410013368 | J5: 217.9414111435279 | K5: 139.88746571677166 | L5: 51.96879147591456 | M5: 3421065.549999983 | N5: 3235683.4500000062 | O5: 5254319 | P5: 4330380 | Q5: 147590106.979043 | R5: 6313 | S5: 5561 | T5: 5070 | U5: 4328 | V5: 2598
A6: 44228 | B6: 24998823 | C6: 45011 | D6: 0 - 3 months | E6: 150 - 200 ARPU | F6: 7729045.240010807 | G6: 12197508.441815477 | H6: 8020110.944868887 | I6: 2969516.3333480866 | J6: 270.989501273366 | K6: 178.18113227586338 | L6: 65.97312508826924 | M6: 4550425.489999975 | N6: 4656805.730000006 | O6: 6849945 | P6: 5403248 | Q6: 203477860.18056297 | R6: 6282 | S6: 5566 | T6: 5046 | U6: 4331 | V6: 2619
A7: 44228 | B7: 24998823 | C7: 35053 | D7: 0 - 3 months | E7: 200 - 300 ARPU | F7: 8433758.434176952 | G7: 13039557.389473453 | H7: 8867437.991783824 | I7: 3394279.921273674 | J7: 371.9954751226272 | K7: 252.97229885555655 | L7: 96.83279380577052 | M7: 4832081.209999981 | N7: 5290285.910900011 | O7: 6884552 | P7: 5222454 | Q7: 205356855.01181412 | R7: 4227 | S7: 3797 | T7: 3448 | U7: 3029 | V7: 1809
A8: 44228 | B8: 24998823 | C8: 543336 | D8: 0 - 3 months | E8: 25 - 50 ARPU | F8: 19228946.653816707 | G8: 33903011.16800365 | H8: 17306437.094691053 | I8: 6477391.698758719 | J8: 62.39787381657694 | K8: 31.852181881360803 | L8: 11.92152130313235 | M8: 14696575.21000209 | N8: 10910009.291799681 | O8: 20683127 | P8: 23311441 | Q8: 625877088.9541445 | R8: 156754 | S8: 132691 | T8: 118857 | U8: 96080 | V8: 55805
A9: 44228 | B9: 24998823 | C9: 18661 | D9: 0 - 3 months | E9: 300 - 500 ARPU | F9: 6979374.354625089 | G9: 10486324.328720557 | H9: 7506629.527181095 | I9: 2945169.2079736646 | J9: 561.9379630631025 | K9: 402.26298307599245 | L9: 157.8248329657395 | M9: 3753827.0600000005 | N9: 4707854.460000003 | O9: 4939253 | P9: 3814994 | Q9: 150898980.45719814 | R9: 1794 | S9: 1632 | T9: 1500 | U9: 1322 | V9: 852
A10: 44228 | B10: 24998823 | C10: 226778 | D10: 0 - 3 months | E10: 50 - 75 ARPU | F10: 13820003.23482102 | G10: 23473532.92598217 | H10: 13189992.250890959 | I10: 4796484.527590749 | J10: 103.50886296722861 | K10: 58.16257419542883 | L10: 21.15057248759028 | M10: 9645476.009999897 | N10: 7829878.391800098 | O10: 14357180 | P10: 14373727 | Q10: 415580481.01681614 | R10: 50487 | S10: 43431 | T10: 39153 | U10: 32589 | V10: 19232
A11: 44228 | B11: 24998823 | C11: 114773 | D11: 0 - 3 months | E11: 75 - 100 ARPU | F11: 9894306.525161508 | G11: 16286878.86858612 | H11: 9794714.913244018 | I11: 3601325.7936546723 | J11: 141.90514205070983 | K11: 85.33988754536361 | L11: 31.37781354198873 | M11: 6541965.709999873 | N11: 5614148.530000046 | O11: 9879655 | P11: 9017273 | Q11: 275030474.1243839 | R11: 21683 | S11: 18773 | T11: 16936 | U11: 14160 | V11: 8462
A12: 44228 | B12: 24998823 | C12: 7987 | D12: 0 - 3 months | E12: GT 500 | F12: 6387649.051058449 | G12: 9048940.138456617 | H12: 7042143.339148301 | I12: 3071863.675570448 | J12: 1132.9585749914381 | K12: 881.7006810001628 | L12: 384.60794736076724 | M12: 2846476.7799999993 | N12: 4715441.870000001 | O12: 3099015 | P12: 2351614 | Q12: 122423838.77688217 | R12: 669 | S12: 609 | T12: 539 | U12: 451 | V12: 274
A13: 44228 | B13: 24998823 | C13: 114225 | D13: 0 - 3 months | E13: Zero or LT Zero ARPU | F13: -125005.78189164707 | G13: -182304.31944256497 | H13: -102566.01360449768 | I13: -90147.01262788152 | J13: -1.596010675793959 | K13: -0.8979296441628162 | L13: -0.7892056259827666 | M13: 46717.53999999981 | N13: 10047.290000000005 | O13: 215141 | P13: 149968 | Q13: 889549782.1098757 | R13: 43905 | S13: 40752 | T13: 38103 | U13: 28696 | V13: 19674
... A73: 44228 | B73: 24998823 | C73: 16750 | D73: GT 24 months | E73: Zero or LT Zero ARPU | F73: -221153.44825725764 | G73: -230858.93091027407 | H73: -205477.63195671415 | I73: -227123.7819047858 | J73: -13.782622740911885 | K73: -12.267321310848606 | L73: -13.559628770434973 | M73: 75682.1305 | N73: 17697.3505 | O73: 132034 | P73: 355522 | Q73: 3258717.4370031357 | R73: 7480 | S73: 6256 | T73: 4837 | U73: 2812 | V73: 1781

Sheet March
A1: DATE | B1: BASE_CNT | C1: SEG_CNT | D1: AON_SLAB | E1: ARPU_SLAB_IND | F1: AVGL3MREV | G1: L1MR | H1: L2MR | I1: L3MR | J1: L1MR_ARPU | K1: L2MR_ARPU | L1: L3MR_ARPU | M1: Voice_Revenue | N1: Data_revenue | O1: OG_MOU | P1: IC_MOU | Q1: TOTAL_DATA_USAGE_MB | R1: CNT_DOLA_7INC | S1: CNT_DOLA_15INC | T1: CNT_DOLA_30INC | U1: CNT_DOLA_60INC | V1: CNT_DOLA_90INC
A2: 44256 | B2: 25101804 | C2: 3250209 | D2: 0 - 3 months | E2: 0 - 10 ARPU | F2: 7528800.246499794 | G2: 13314418.678070998 | H2: 5974911.257270543 | I2: 3297070.804185122 | J2: 4.096480773412109 | K2: 1.8383160151456546 | L2: 1.0144180894782833 | M2: 7127026.5899937255 | N2: 3401556.9100009734 | O2: 8368579 | P2: 16829965 | Q2: 835653942.0473404 | R2: 2445490 | S2: 2263728 | T2: 2099572 | U2: 1527653 | V2: 839303
A3: 44256 | B3: 25101804 | C3: 1194287 | D3: 0 - 3 months | E3: 10 - 25 ARPU | F3: 17513450.499558263 | G3: 29295873.61158921 | H3: 15573124.39484849 | I3: 7671353.492252983 | J3: 24.530011305146257 | K3: 13.03968342186467 | L3: 6.423375195621307 | M3: 12381499.52000359 | N3: 8514924.280000404 | O3: 16647202 | P3: 21321985 | Q3: 705612926.9225492 | R3: 680014 | S3: 624105 | T3: 580778 | U3: 444583 | V3: 239718
A4: 44256 | B4: 25101804 | C4: 71296 | D4: 0 - 3 months | E4: 100 - 125 ARPU | F4: 7948333.279483147 | G4: 12959038.417453004 | H4: 8324889.883616472 | I4: 2561071.5373800676 | J4: 181.76389162720216 | K4: 116.76517453456675 | L4: 35.92167214682546 | M4: 5218064.619999944 | N4: 4266597.670900022 | O4: 7884788 | P4: 7129665 | Q4: 236342359.33057785 | R4: 12393 | S4: 10731 | T4: 9566 | U4: 8254 | V4: 5534
A5: 44256 | B5: 25101804 | C5: 44478 | D5: 0 - 3 months | E5: 125 - 150 ARPU | F5: 6071299.28057138 | G5: 9787056.050424503 | H5: 6470298.0160775045 | I5: 1956543.775212158 | J5: 220.0426289496943 | K5: 145.47187409680078 | L5: 43.9890232297351 | M5: 3892846.2399999844 | N5: 3303574.8000000063 | O5: 5918630 | P5: 5066168 | Q5: 173687133.10041237 | R5: 7228 | S5: 6332 | T5: 5723 | U5: 5023 | V5: 3371
A6: 44256 | B6: 25101804 | C6: 49365 | D6: 0 - 3 months | E6: 150 - 200 ARPU | F6: 8474688.430611968 | G6: 13445830.51967079 | H6: 9121219.750908596 | I6: 2857015.0212566084 | J6: 272.3757828354257 | K6: 184.77098654732293 | L6: 57.87531695040228 | M6: 5161457.3799999785 | N6: 4812024.510900016 | O6: 7843088 | P6: 6382376 | Q6: 235514156.26015377 | R6: 7436 | S6: 6591 | T6: 5931 | U6: 5169 | V6: 3479
A7: 44256 | B7: 25101804 | C7: 38755 | D7: 0 - 3 months | E7: 200 - 300 ARPU | F7: 9326633.818307523 | G7: 14646311.454417115 | H7: 10153468.61692927 | I7: 3180121.38357625 | J7: 377.92056391219495 | K7: 261.99119125091653 | L7: 82.05706060059993 | M7: 5465281.049999975 | N7: 5619348.350000009 | O7: 8071245 | P7: 6126044 | Q7: 242028376.8068018 | R7: 4954 | S7: 4428 | T7: 4010 | U7: 3545 | V7: 2411
A8: 44256 | B8: 25101804 | C8: 558826 | D8: 0 - 3 months | E8: 25 - 50 ARPU | F8: 19834139.622404084 | G8: 35034871.21651034 | H8: 18236028.067272477 | I8: 6231519.583432234 | J8: 62.69370289948989 | K8: 32.63274805981196 | L8: 11.15109100763428 | M8: 15786280.120002918 | N8: 10640750.840899693 | O8: 21004127 | P8: 25576958 | Q8: 672030591.8773966 | R8: 173546 | S8: 147546 | T8: 129419 | U8: 105922 | V8: 66532
A9: 44256 | B9: 25101804 | C9: 20581 | D9: 0 - 3 months | E9: 300 - 500 ARPU | F9: 7701114.277586136 | G9: 11753329.227168404 | H9: 8539551.95597574 | I9: 2810461.6496142824 | J9: 571.0766836970217 | K9: 414.9240540292376 | L9: 136.5561269916079 | M9: 4225998.280000005 | N9: 4974952.661800003 | O9: 5893412 | P9: 4235596 | Q9: 180811000.8515234 | R9: 2186 | S9: 1952 | T9: 1793 | U9: 1586 | V9: 1052
A10: 44256 | B10: 25101804 | C10: 241880 | D10: 0 - 3 months | E10: 50 - 75 ARPU | F10: 14760491.608335003 | G10: 25112184.57108218 | H10: 14559330.866660666 | I10: 4609959.387262979 | J10: 103.82083913958235 | K10: 60.19237169944049 | L10: 19.05886963478989 | M10: 10702352.260000106 | N10: 7842755.370000107 | O10: 15144462 | P10: 16566669 | Q10: 476338867.1304922 | R10: 57124 | S10: 48777 | T10: 43123 | U10: 36311 | V10: 23619
A11: 44256 | B11: 25101804 | C11: 124853 | D11: 0 - 3 months | E11: 75 - 100 ARPU | F11: 10766871.581286646 | G11: 17889730.111641943 | H11: 11002052.95161767 | I11: 3408831.680600565 | J11: 143.28634563560303 | K11: 88.12005279502831 | L11: 27.302761492319487 | M11: 7368089.039999812 | N11: 5757466.250900048 | O11: 10982853 | P11: 10764493 | Q11: 330979818.841424 | R11: 24586 | S11: 21255 | T11: 18900 | U11: 16166 | V11: 10790
A12: 44256 | B12: 25101804 | C12: 8757 | D12: 0 - 3 months | E12: GT 500 | F12: 7016023.948556788 | G12: 10208413.875780776 | H12: 7952407.766877605 | I12: 2887250.2030119756 | J12: 1165.743276896286 | K12: 908.1201058441937 | L12: 329.70768562429777 | M12: 3203709.710000001 | N12: 4886346.520000001 | O12: 3576058 | P12: 2623504 | Q12: 140684636.83271503 | R12: 773 | S12: 701 | T12: 652 | U12: 555 | V12: 347
A13: 44256 | B13: 25101804 | C13: 84902 | D13: 0 - 3 months | E13: Zero or LT Zero ARPU | F13: -154338.8839661166 | G13: -259254.53789963832 | H13: -125879.13928065512 | I13: -77882.9747180588 | J13: -3.053573978229468 | K13: -1.4826404475825672 | L13: -0.9173279159272903 | M13: 63552.239999999925 | N13: 12176.730000000007 | O13: 256826 | P13: 151213 | Q13: 238384094.528862 | R13: 34632 | S13: 32379 | T13: 30169 | U13: 24513 | V13: 16435
... A73: 44256 | B73: 25101804 | C73: 16153 | D73: GT 24 months | E73: Zero or LT Zero ARPU | F73: -238708.37182445027 | G73: -281847.09724168514 | H73: -226870.52842946036 | I73: -207407.4898022052 | J73: -17.44859142213119 | K73: -14.045101741438765 | L73: -12.840183854528894 | M73: 98567.95299999998 | N73: 19369.350000000006 | O73: 152260 | P73: 418196 | Q73: 3360846.8789453506 | R73: 7211 | S73: 6062 | T73: 4819 | U73: 3127 | V73: 1978

Sheet April
A1: DATE | B1: BASE_CNT | C1: SEG_CNT | D1: AON_SLAB | E1: ARPU_SLAB_IND | F1: AVGL3MREV | G1: L1MR | H1: L2MR | I1: L3MR | J1: L1MR_ARPU | K1: L2MR_ARPU | L1: L3MR_ARPU | M1: Voice_Revenue | N1: Data_revenue | O1: OG_MOU | P1: IC_MOU | Q1: TOTAL_DATA_USAGE_MB | R1: CNT_DOLA_7INC | S1: CNT_DOLA_15INC | T1: CNT_DOLA_30INC | U1: CNT_DOLA_60INC | V1: CNT_DOLA_90INC
A2: 44287 | B2: 24866757 | C2: 3090305 | D2: 0 - 3 months | E2: 0 - 10 ARPU | F2: 7508578.726277695 | G2: 12811655.871401364 | H2: 6590991.758908621 | I2: 3123088.548550954 | J2: 4.145757739576308 | K2: 2.1327965229673516 | L2: 1.0106085155190034 | M2: 6538204.989994494 | N2: 3068311.0100008287 | O2: 8870109 | P2: 15497069 | Q2: 1038441127.5381393 | R2: 2380917 | S2: 2167884 | T2: 2005323 | U2: 1423906 | V2: 0
A3: 44287 | B3: 24866757 | C3: 1215367 | D3: 0 - 3 months | E3: 10 - 25 ARPU | F3: 17668521.861553974 | G3: 27965740.581564724 | H3: 16572148.59284529 | I3: 8467676.410271453 | J3: 23.010120055559124 | K3: 13.635509761944574 | L3: 6.967176507401841 | M3: 11569070.56000247 | N3: 7874999.5800006045 | O3: 15900098 | P3: 19684114 | Q3: 666784951.6728964 | R3: 733711 | S3: 665007 | T3: 622559 | U3: 458784 | V3: 0
A4: 44287 | B4: 24866757 | C4: 73394 | D4: 0 - 3 months | E4: 100 - 125 ARPU | F4: 8180512.827341795 | G4: 12559208.315112464 | H4: 9014215.862084812 | I4: 2968114.3048283127 | J4: 171.12036835589373 | K4: 122.81952015266658 | L4: 40.440830378890816 | M4: 5162758.299999939 | N4: 3744558.4609000282 | O4: 7438607 | P4: 7502983 | Q4: 240117623.38959122 | R4: 13852 | S4: 11847 | T4: 10552 | U4: 9172 | V4: 0
A5: 44287 | B5: 24866757 | C5: 46769 | D5: 0 - 3 months | E5: 125 - 150 ARPU | F5: 6389108.338938681 | G5: 9710413.13220021 | H5: 7095337.276531128 | I5: 2361574.6080847573 | J5: 207.62498946311038 | K5: 151.71026270673156 | L5: 50.494443073077406 | M5: 3872358.7499999846 | N5: 3007234.8700000076 | O5: 5697010 | P5: 5528277 | Q5: 183320504.12676907 | R5: 8109 | S5: 6933 | T5: 6240 | U5: 5432 | V5: 0
A6: 44287 | B6: 24866757 | C6: 52132 | D6: 0 - 3 months | E6: 150 - 200 ARPU | F6: 8958342.87237716 | G6: 13464892.583273577 | H6: 10060386.47478993 | I6: 3349749.559068064 | J6: 258.2845964719093 | K6: 192.9791006443246 | L6: 64.25515152052606 | M6: 5242872.959999962 | N6: 4359831.430000012 | O6: 7813642 | P6: 7085479 | Q6: 247742616.63917065 | R6: 8012 | S6: 7004 | T6: 6343 | U6: 5485 | V6: 0
A7: 44287 | B7: 24866757 | C7: 42093 | D7: 0 - 3 months | E7: 200 - 300 ARPU | F7: 10127407.345004736 | G7: 14908437.71284032 | H7: 11624216.223342456 | I7: 3849568.0988315847 | J7: 354.1785501826983 | K7: 276.1555656128681 | L7: 91.4538782893019 | M7: 5664973.859999969 | N7: 5167019.450000012 | O7: 8450159 | P7: 7112176 | Q7: 261458300.79828358 | R7: 5710 | S7: 5052 | T7: 4589 | U7: 4099 | V7: 0
A8: 44287 | B8: 24866757 | C8: 549597 | D8: 0 - 3 months | E8: 25 - 50 ARPU | F8: 19509109.854399268 | G8: 32752873.89818984 | H8: 19045509.42689067 | I8: 6728946.238121933 | J8: 59.59434621766465 | K8: 34.65359058890545 | L8: 12.243418792536955 | M8: 14776971.8900024 | N8: 9254108.370000046 | O8: 18125096 | P8: 23814792 | Q8: 620983648.7200394 | R8: 187261 | S8: 155617 | T8: 137538 | U8: 112226 | V8: 0
A9: 44287 | B9: 24866757 | C9: 22178 | D9: 0 - 3 months | E9: 300 - 500 ARPU | F9: 8320106.3396346625 | G9: 11996062.910370322 | H9: 9618587.350592652 | I9: 3345668.757941067 | J9: 540.8992204152909 | K9: 433.69949276727624 | L9: 150.8552961466799 | M9: 4395544.779999984 | N9: 4697774.060000003 | O9: 6258158 | P9: 4898473 | Q9: 191263682.86850452 | R9: 2380 | S9: 2089 | T9: 1899 | U9: 1685 | V9: 0
A10: 44287 | B10: 24866757 | C10: 242149 | D10: 0 - 3 months | E10: 50 - 75 ARPU | F10: 14786820.080210166 | G10: 23837047.59734327 | H10: 15399104.1898993 | I10: 5124308.4533888325 | J10: 98.43958718534155 | K10: 63.5935072616418 | L10: 21.16179894770919 | M10: 10226997.479999967 | N10: 6851888.100900117 | O10: 13551559 | P10: 16095580 | Q10: 461224183.33296585 | R10: 62330 | S10: 52100 | T10: 46308 | U10: 38927 | V10: 0
A11: 44287 | B11: 24866757 | C11: 126789 | D11: 0 - 3 months | E11: 75 - 100 ARPU | F11: 10937544.208987921 | G11: 17174269.806418743 | H11: 11785026.317004448 | I11: 3853336.503540898 | J11: 135.45551906252706 | K11: 92.94991140402124 | L11: 30.391725650812752 | M11: 7155610.309999771 | N11: 5054938.900900038 | O11: 10032947 | P11: 10896968 | Q11: 332549288.38379765 | R11: 26877 | S11: 22688 | T11: 20115 | U11: 17187 | V11: 0
A12: 44287 | B12: 24866757 | C12: 9873 | D12: 0 - 3 months | E12: GT 500 | F12: 7941731.655558646 | G12: 10642589.511318654 | H12: 9643798.743086647 | I12: 3538806.7122706454 | J12: 1077.9489021896743 | K12: 976.7850443721916 | L12: 358.4327673726978 | M12: 3459536.1099999975 | N12: 4926135.6899999995 | O12: 4226322 | P12: 3467367 | Q12: 150650636.22136497 | R12: 773 | S12: 693 | T12: 633 | U12: 527 | V12: 0
A13: 44287 | B13: 24866757 | C13: 86115 | D13: 0 - 3 months | E13: Zero or LT Zero ARPU | F13: -177441.13084585365 | G13: -257911.31543013605 | H13: -185036.9099970256 | I13: -89375.16711040362 | J13: -2.9949638904968476 | K13: -2.1487186900891317 | L13: -1.0378582954236035 | M13: 42069.22999999988 | N13: 10654.890000000003 | O13: 316092 | P13: 145488 | Q13: 435975425.37522316 | R13: 32476 | S13: 30620 | T13: 29186 | U13: 23082 | V13: 0
... A73: 44287 | B73: 24866757 | C73: 17573 | D73: GT 24 months | E73: Zero or LT Zero ARPU | F73: -259048.45979647816 | G73: -274650.2451201291 | H73: -289088.7754667324 | I73: -213406.35880257358 | J73: -15.629104030053439 | K73: -16.4507355298886 | L73: -12.143991282226915 | M73: 86366.5601 | N73: 19531.9903 | O73: 152765 | P73: 414447 | Q73: 3010322.133072853 | R73: 9496 | S73: 8211 | T73: 6100 | U73: 4311 | V73: 0

Sheet Compiled
A1: DATE | B1: BASE_CNT | C1: SEG_CNT | D1: AON_SLAB | E1: ARPU_SLAB_IND | F1: AVGL3MREV | G1: L1MR | H1: L2MR | I1: L3MR | J1: L1MR_ARPU | K1: L2MR_ARPU | L1: L3MR_ARPU | M1: Voice_Revenue | N1: Data_revenue | O1: OG_MOU | P1: IC_MOU | Q1: TOTAL_DATA_USAGE_MB | R1: CNT_DOLA_7INC | S1: CNT_DOLA_15INC | T1: CNT_DOLA_30INC | U1: CNT_DOLA_60INC | V1: CNT_DOLA_90INC | W1: ARPU_Seg | Z1: OLD_seg_asper PPT
A2: 44228 | B2: 24998823 | C2: 3305509 | D2: 0 - 3 months | E2: 0 - 10 ARPU | F2: 7722060.6 | G2: 13288873 | H2: 6501996 | I2: 3375312.6 | J2: 4.0202199 | K2: 1.9670181 | L2: 1.0211173 | M2: 7029842.7 | N2: 3357101.6 | O2: 8381050 | P2: 16598795 | Q2: 1.024369e+09 | R2: 2374613 | S2: 2164288 | T2: 2003728 | U2: 1419706 | V2: 770951 | W2: =VLOOKUP(E2,Segments!$B$1:$C$12,2,0) -> Low | Z2: Low
A3: 44228 | B3: 24998823 | C3: 1183742 | D3: 0 - 3 months | E3: 10 - 25 ARPU | F3: 17434476 | G3: 29233559 | H3: 15194448 | I3: 7875420.5 | J3: 24.695888 | K3: 12.835945 | L3: 6.6529873 | M3: 12017722 | N3: 8628754.2 | O3: 16673168 | P3: 20410798 | Q3: 6.8012636e+08 | R3: 640519 | S3: 584395 | T3: 549121 | U3: 404751 | V3: 223102 | W3: =VLOOKUP(E3,Segments!$B$1:$C$12,2,0) -> Low | Z3: Low
A4: 44228 | B4: 24998823 | C4: 64610 | D4: 0 - 3 months | E4: 100 - 125 ARPU | F4: 7197556.8 | G4: 11626685 | H4: 7296940.2 | I4: 2669045.1 | J4: 179.95179 | K4: 112.93825 | L4: 41.310093 | M4: 4573523.7 | N4: 4066469.9 | O4: 7071441 | P4: 6097574 | Q4: 1.970366e+08 | R4: 10753 | S4: 9404 | T4: 8563 | U4: 7329 | V4: 4424 | W4: =VLOOKUP(E4,Segments!$B$1:$C$12,2,0) -> Medium | Z4: Medium
A5: 44228 | B5: 24998823 | C5: 40777 | D5: 0 - 3 months | E5: 125 - 150 ARPU | F5: 5570106.5 | G5: 8886996.9 | H5: 5704191.2 | I5: 2119131.4 | J5: 217.94141 | K5: 139.88747 | L5: 51.968791 | M5: 3421065.5 | N5: 3235683.5 | O5: 5254319 | P5: 4330380 | Q5: 1.4759011e+08 | R5: 6313 | S5: 5561 | T5: 5070 | U5: 4328 | V5: 2598 | W5: =VLOOKUP(E5,Segments!$B$1:$C$12,2,0) -> High | Z5: High
A6: 44228 | B6: 24998823 | C6: 45011 | D6: 0 - 3 months | E6: 150 - 200 ARPU | F6: 7729045.2 | G6: 12197508 | H6: 8020110.9 | I6: 2969516.3 | J6: 270.9895 | K6: 178.18113 | L6: 65.973125 | M6: 4550425.5 | N6: 4656805.7 | O6: 6849945 | P6: 5403248 | Q6: 2.0347786e+08 | R6: 6282 | S6: 5566 | T6: 5046 | U6: 4331 | V6: 2619 | W6: =VLOOKUP(E6,Segments!$B$1:$C$12,2,0) -> High | Z6: High
A7: 44228 | B7: 24998823 | C7: 35053 | D7: 0 - 3 months | E7: 200 - 300 ARPU | F7: 8433758.4 | G7: 13039557 | H7: 8867438 | I7: 3394279.9 | J7: 371.99548 | K7: 252.9723 | L7: 96.832794 | M7: 4832081.2 | N7: 5290285.9 | O7: 6884552 | P7: 5222454 | Q7: 2.0535686e+08 | R7: 4227 | S7: 3797 | T7: 3448 | U7: 3029 | V7: 1809 | W7: =VLOOKUP(E7,Segments!$B$1:$C$12,2,0) -> High | Z7: High
A8: 44228 | B8: 24998823 | C8: 543336 | D8: 0 - 3 months | E8: 25 - 50 ARPU | F8: 19228947 | G8: 33903011 | H8: 17306437 | I8: 6477391.7 | J8: 62.397874 | K8: 31.852182 | L8: 11.921521 | M8: 14696575 | N8: 10910009 | O8: 20683127 | P8: 23311441 | Q8: 6.2587709e+08 | R8: 156754 | S8: 132691 | T8: 118857 | U8: 96080 | V8: 55805 | W8: =VLOOKUP(E8,Segments!$B$1:$C$12,2,0) -> Medium | Z8: Medium
A9: 44228 | B9: 24998823 | C9: 18661 | D9: 0 - 3 months | E9: 300 - 500 ARPU | F9: 6979374.4 | G9: 10486324 | H9: 7506629.5 | I9: 2945169.2 | J9: 561.93796 | K9: 402.26298 | L9: 157.82483 | M9: 3753827.1 | N9: 4707854.5 | O9: 4939253 | P9: 3814994 | Q9: 1.5089898e+08 | R9: 1794 | S9: 1632 | T9: 1500 | U9: 1322 | V9: 852 | W9: =VLOOKUP(E9,Segments!$B$1:$C$12,2,0) -> VHigh | Z9: VHigh
A10: 44228 | B10: 24998823 | C10: 226778 | D10: 0 - 3 months | E10: 50 - 75 ARPU | F10: 13820003 | G10: 23473533 | H10: 13189992 | I10: 4796484.5 | J10: 103.50886 | K10: 58.162574 | L10: 21.150572 | M10: 9645476 | N10: 7829878.4 | O10: 14357180 | P10: 14373727 | Q10: 4.1558048e+08 | R10: 50487 | S10: 43431 | T10: 39153 | U10: 32589 | V10: 19232 | W10: =VLOOKUP(E10,Segments!$B$1:$C$12,2,0) -> Medium | Z10: Medium
A11: 44228 | B11: 24998823 | C11: 114773 | D11: 0 - 3 months | E11: 75 - 100 ARPU | F11: 9894306.5 | G11: 16286879 | H11: 9794714.9 | I11: 3601325.8 | J11: 141.90514 | K11: 85.339888 | L11: 31.377814 | M11: 6541965.7 | N11: 5614148.5 | O11: 9879655 | P11: 9017273 | Q11: 2.7503047e+08 | R11: 21683 | S11: 18773 | T11: 16936 | U11: 14160 | V11: 8462 | W11: =VLOOKUP(E11,Segments!$B$1:$C$12,2,0) -> Medium | Z11: Medium
A12: 44228 | B12: 24998823 | C12: 7987 | D12: 0 - 3 months | E12: GT 500 | F12: 6387649.1 | G12: 9048940.1 | H12: 7042143.3 | I12: 3071863.7 | J12: 1132.9586 | K12: 881.70068 | L12: 384.60795 | M12: 2846476.8 | N12: 4715441.9 | O12: 3099015 | P12: 2351614 | Q12: 1.2242384e+08 | R12: 669 | S12: 609 | T12: 539 | U12: 451 | V12: 274 | W12: =VLOOKUP(E12,Segments!$B$1:$C$12,2,0) -> VHigh | Z12: VHigh
A13: 44228 | B13: 24998823 | C13: 114225 | D13: 0 - 3 months | E13: Zero or LT Zero ARPU | F13: -125005.78 | G13: -182304.32 | H13: -102566.01 | I13: -90147.013 | J13: -1.5960107 | K13: -0.89792964 | L13: -0.78920563 | M13: 46717.54 | N13: 10047.29 | O13: 215141 | P13: 149968 | Q13: 8.8954978e+08 | R13: 43905 | S13: 40752 | T13: 38103 | U13: 28696 | V13: 19674 | W13: =VLOOKUP(E13,Segments!$B$1:$C$12,2,0) -> Low | Z13: Low
... A217: 44287 | B217: 24866757 | C217: 17573 | D217: GT 24 months | E217: Zero or LT Zero ARPU | F217: -259048.46 | G217: -274650.25 | H217: -289088.78 | I217: -213406.36 | J217: -15.629104 | K217: -16.450736 | L217: -12.143991 | M217: 86366.56 | N217: 19531.99 | O217: 152765 | P217: 414447 | Q217: 3010322.1 | R217: 9496 | S217: 8211 | T217: 6100 | U217: 4311 | V217: 0 | W217: =VLOOKUP(E217,Segments!$B$1:$C$12,2,0) -> Low | Z217: Low

Sheet pivot
A1: AON_SLAB | B1: (All)
A3: Row Labels | B3: Sum of SEG_CNT | C3: Sum of CNT_DOLA_7INC | D3: Sum of CNT_DOLA_15INC | E3: Sum of CNT_DOLA_30INC | F3: Sum of CNT_DOLA_60INC | G3: Sum of CNT_DOLA_90INC
A4: Feb | B4: 24998823 | C4: 9285735 | D4: 7924230 | E4: 6872269 | F4: 4379072 | G4: 2304891
A5: Mar | B5: 25101804 | C5: 9585889 | D5: 8330090 | E5: 7216463 | F5: 4631907 | G5: 2516368
A6: Apr | B6: 24866757 | C6: 9814495 | D6: 8213684 | E6: 6992278 | F6: 4493210 | G6: 0
A7: Grand Total | B7: 74967384 | C7: 28686119 | D7: 24468004 | E7: 21081010 | F7: 13504189 | G7: 4821259

Sheet Static_Base
A1: OLD_DATA_Shared by Anda_for comparion purpose
A2: ALL AON
A3: Month | B3: SEG_CNT | C3: CNT_DOLA_7INC | D3: CNT_DOLA_15INC | E3: CNT_DOLA_30INC | F3: CNT_DOLA_60INC | G3: CNT_DOLA_90INC | H3: DOLA>=7D% | I3: DOLA>=15D% | J3: DOLA>=30D% | K3: DOLA>=60D% | L3: DOLA>=90D% | Z3: 44287 | AA3: 43832 | AB3: =AA3-Z3 -> -455 | AD3: 44287 | AE3: 43832 | AF3: =AE3-AD3 -> -455
A4: Feb | B4: 24998823 | C4: 9366635 | D4: 8016254 | E4: 6828424 | F4: 4396922 | G4: 2271466 | H4: 0.37468304 | I4: 0.32066526 | J4: 0.27314982 | K4: 0.17588516 | L4: 0.090862918 | N4: =B22-B4 -> 0 | O4: =C22-C4 -> -80900 | P4: =D22-D4 -> -92024 | Q4: =E22-E4 -> 43845 | R4: =F22-F4 -> -17850 | S4: =G22-G4 -> 33425 | T4: =H22-H4 -> -0.0032361524 | U4: =I22-I4 -> -0.0036811333 | ... X4: =L22-L4 -> 0.0013370629 | Z4: =Z3+6 -> 44293 | AA4: =Z4-$Z$3 -> 6 | AD4: =AD3+7 -> 44294 | AE4: =AD4-$Z$3 -> 7
A5: Mar | B5: 25101804 | C5: 9667602 | D5: 8428184 | E5: 7190489 | F5: 4608056 | G5: 2467051 | H5: 0.38513575 | I5: 0.33576009 | J5: 0.28645308 | K5: 0.18357469 | L5: 0.098281821 | N5: =B23-B5 -> 0 | O5: =C23-C5 -> -81713 | P5: =D23-D5 -> -98094 | Q5: =E23-E5 -> 25974 | R5: =F23-F5 -> 23851 | S5: =G23-G5 -> 49317 | T5: =H23-H5 -> -0.003255264 | U5: =I23-I5 -> -0.0039078466 | ... X5: =L23-L5 -> 0.0019646795 | Z5: =Z3+14 -> 44301 | AA5: =Z5-$Z$3 -> 14 | AD5: =AD3+15 -> 44302 | AE5: =AD5-$Z$3 -> 15
A6: Apr | B6: 24866757 | C6: 9856922 | D6: 8298457 | E6: 7083198 | F6: 4490788 | H6: 0.39638953 | I6: 0.3337169 | J6: 0.28484607 | K6: 0.18059404 | L6: 0 | N6: =B24-B6 -> 0 | O6: =C24-C6 -> -42427 | P6: =D24-D6 -> -84773 | Q6: =E24-E6 -> -90920 | R6: =F24-F6 -> 2422 | S6: =G24-G6 -> 0 | T6: =H24-H6 -> -0.0017061734 | U6: =I24-I6 -> -0.0034090895 | ... X6: =L24-L6 -> 0 | Z6: =Z3+29 -> 44316 | AA6: =Z6-$Z$3 -> 29 | AD6: =AD3+30 -> 44317 | AE6: =AD6-$Z$3 -> 30
Z7: =Z3+59 -> 44346 | AA7: =Z7-$Z$3 -> 59 | AD7: =AD3+60 -> 44347 | AE7: =AD7-$Z$3 -> 60
A8: AON <90 | Z8: =Z3+89 -> 44376 | AA8: =Z8-$Z$3 -> 89 | AD8: =AD3+90 -> 44377 | AE8: =AD8-$Z$3 -> 90
A9: Month | B9: SEG_CNT | C9: CNT_DOLA_7INC | D9: CNT_DOLA_15INC | E9: CNT_DOLA_30INC | F9: CNT_DOLA_60INC | G9: CNT_DOLA_90INC | H9: DOLA>=7D% | I9: DOLA>=15D% | J9: DOLA>=30D% | K9: DOLA>=60D% | L9: DOLA>=90D%
A10: Feb | B10: 5562568 | C10: 3278782 | D10: 2978593 | E10: 2751023 | F10: 2007202 | G10: 1084847 | H10: 0.58943675 | I10: 0.53547085 | J10: 0.49455989 | K10: 0.36084089 | L10: 0.19502629 | N10: =B28-B10 -> 137894 | O10: =C28-C10 -> 39217 | P10: =D28-D10 -> 32306 | Q10: =E28-E10 -> 39041 | R10: =F28-F10 -> 9570 | S10: =G28-G10 -> 24955 | T10: =H28-H10 -> -0.007378839 | U10: =I28-I10 -> -0.0072857633 | ... X10: =L28-L10 -> -0.00033996459 | Z10: Deloitte | AD10: MTN
A11: Mar | B11: 5688189 | C11: 3499676 | D11: 3221049 | E11: 2966751 | F11: 2178655 | G11: 1189794 | H11: 0.61525311 | I11: 0.56626969 | J11: 0.52156337 | K11: 0.38301382 | L11: 0.20916921 | N11: =B29-B11 -> 0 | O11: =C29-C11 -> -49314 | P11: =D29-D11 -> -52524 | Q11: =E29-E11 -> -37115 | R11: =F29-F11 -> 625 | S11: =G29-G11 -> 22797 | T11: =H29-H11 -> -0.0086695432 | U11: =I29-I11 -> -0.0092338704 | ... X11: =L29-L11 -> 0.0040077782
A12: Apr | B12: 5556761 | C12: 3505920 | D12: 3174308 | E12: 2939017 | F12: 2108729 | H12: 0.6309287 | I12: 0.57125149 | J12: 0.5289083 | K12: 0.37948888 | L12: 0 | N12: =B30-B12 -> 0 | O12: =C30-C12 -> -43512 | P12: =D30-D12 -> -46774 | Q12: =E30-E12 -> -47732 | R12: =F30-F12 -> -8217 | S12: =G30-G12 -> 0 | T12: =H30-H12 -> -0.0078304609 | U12: =I30-I12 -> -0.0084174936 | ... X12: =L30-L12 -> 0 | AD12: >=
A14: AON >=90
A15: Month | B15: SEG_CNT | C15: CNT_DOLA_7INC | D15: CNT_DOLA_15INC | E15: CNT_DOLA_30INC | F15: CNT_DOLA_60INC | G15: CNT_DOLA_90INC | H15: DOLA>=7D% | I15: DOLA>=15D% | J15: DOLA>=30D% | K15: DOLA>=60D% | L15: DOLA>=90D%
A16: Feb | B16: 19436255 | C16: 6087853 | D16: 5037661 | E16: 4077401 | F16: 2389720 | G16: 1186619 | H16: 0.3132215 | I16: 0.25918887 | J16: 0.20978326 | K16: 0.12295167 | L16: 0.061051833 | N16: =B33-B16 -> -137894 | O16: =C33-C16 -> -120117 | P16: =D33-D16 -> -124330 | Q16: =E33-E16 -> 4804 | R16: =F33-F16 -> -27420 | S16: =G33-G16 -> 8470 | T16: =H33-H16 -> -0.0039861227 | U16: =I33-I16 -> -0.0045905147 | ... X16: =L33-L16 -> 0.00087513554
A17: Mar | B17: 19413615 | C17: 6167926 | D17: 5207135 | E17: 4223738 | F17: 2429401 | G17: 1277257 | H17: 0.31771136 | I17: 0.26822078 | J17: 0.21756577 | K17: 0.12513903 | L17: 0.065791817 | N17: =B34-B17 -> 0 | O17: =C34-C17 -> -32399 | P17: =D34-D17 -> -45570 | Q17: =E34-E17 -> 63089 | R17: =F34-F17 -> 23226 | S17: =G34-G17 -> 26520 | T17: =H34-H17 -> -0.0016688803 | U17: =I34-I17 -> -0.0023473217 | ... X17: =L34-L17 -> 0.0013660516
A18: Apr | B18: 19309996 | C18: 6351002 | D18: 5124149 | E18: 4144181 | F18: 2382059 | G18: 0 | H18: 0.32889712 | I18: 0.26536251 | J18: 0.21461325 | K18: 0.12335886 | L18: 0 | N18: =B35-B18 -> 0 | O18: =C35-C18 -> 1085 | P18: =D35-D18 -> -37999 | Q18: =E35-E18 -> -43188 | R18: =F35-F18 -> 10639 | S18: =G35-G18 -> 0 | T18: =H35-H18 -> 5.6188515e-05 | U18: =I35-I18 -> -0.0019678409 | ... X18: =L35-L18 -> 0
A20: NEW_DATA_With filters agreed by Anda
A21: Overall AON | B21: SEG_CNT | C21: CNT_DOLA_7INC | D21: CNT_DOLA_15INC | E21: CNT_DOLA_30INC | F21: CNT_DOLA_60INC | G21: CNT_DOLA_90INC | H21: DOLA>=7D% | I21: DOLA>=15D% | J21: DOLA>=30D% | K21: DOLA>=60D% | L21: DOLA>=90D%
A22: Feb | B22: 24998823 | C22: 9285735 | D22: 7924230 | E22: 6872269 | F22: 4379072 | G22: 2304891 | H22: =C22/$B22 -> 0.37144689 | I22: =D22/$B22 -> 0.31698412 | J22: =E22/$B22 -> 0.2749037 | K22: =F22/$B22 -> 0.17517113 | L22: =G22/$B22 -> 0.092199981
A23: Mar | B23: 25101804 | C23: 9585889 | D23: 8330090 | E23: 7216463 | F23: 4631907 | G23: 2516368 | H23: =C23/$B23 -> 0.38188048 | I23: =D23/$B23 -> 0.33185224 | J23: =E23/$B23 -> 0.28748782 | K23: =F23/$B23 -> 0.18452487 | L23: =G23/$B23 -> 0.1002465
A24: Apr | B24: 24866757 | C24: 9814495 | D24: 8213684 | E24: 6992278 | F24: 4493210 | G24: 0 | H24: =C24/$B24 -> 0.39468335 | I24: =D24/$B24 -> 0.33030781 | J24: =E24/$B24 -> 0.28118978 | K24: =F24/$B24 -> 0.18069143 | L24: =G24/$B24 -> 0 | N24: =B24-B25 -> 1082 | O24: =C24-C25 -> -10755
A25: Apr Exact Filters | B25: 24865675 | C25: =C31+C36 -> 9825250
A27: AON<90 | B27: SEG_CNT | C27: CNT_DOLA_7INC | D27: CNT_DOLA_15INC | E27: CNT_DOLA_30INC | F27: CNT_DOLA_60INC | G27: CNT_DOLA_90INC | H27: DOLA>=7D% | I27: DOLA>=15D% | J27: DOLA>=30D% | K27: DOLA>=60D% | L27: DOLA>=90D%
A28: Feb | B28: 5700462 | C28: 3317999 | D28: 3010899 | E28: 2790064 | F28: 2016772 | G28: 1109802 | H28: =C28/$B28 -> 0.58205791 | I28: =D28/$B28 -> 0.52818508 | J28: =E28/$B28 -> 0.48944524 | K28: =F28/$B28 -> 0.35379097 | L28: =G28/$B28 -> 0.19468633
A29: Mar | B29: 5688189 | C29: 3450362 | D29: 3168525 | E29: 2929636 | F29: 2179280 | G29: 1212591 | H29: =C29/$B29 -> 0.60658357 | I29: =D29/$B29 -> 0.55703582 | J29: =E29/$B29 -> 0.51503844 | K29: =F29/$B29 -> 0.3831237 | L29: =G29/$B29 -> 0.21317699
A30: Apr | B30: 5556761 | C30: 3462408 | D30: 3127534 | E30: 2891285 | F30: 2100512 | G30: 0 | H30: =C30/$B30 -> 0.62309824 | I30: =D30/$B30 -> 0.562834 | J30: =E30/$B30 -> 0.5203184 | K30: =F30/$B30 -> 0.37801014 | L30: =G30/$B30 -> 0 | N30: =B30-B31 -> 17 | O30: =C30-C31 -> -75
A31: Apr Exact Filters | B31: 5556744 | C31: 3462483
A32: AON>=90 | B32: SEG_CNT | C32: CNT_DOLA_7INC | D32: CNT_DOLA_15INC | E32: CNT_DOLA_30INC | F32: CNT_DOLA_60INC | G32: CNT_DOLA_90INC | H32: DOLA>=7D% | I32: DOLA>=15D% | J32: DOLA>=30D% | K32: DOLA>=60D% | L32: DOLA>=90D%
A33: Feb | B33: 19298361 | C33: 5967736 | D33: 4913331 | E33: 4082205 | F33: 2362300 | G33: 1195089 | H33: =C33/$B33 -> 0.30923538 | I33: =D33/$B33 -> 0.25459836 | J33: =E33/$B33 -> 0.21153118 | K33: =F33/$B33 -> 0.12240936 | L33: =G33/$B33 -> 0.061926969
A34: Mar | B34: 19413615 | C34: 6135527 | D34: 5161565 | E34: 4286827 | F34: 2452627 | G34: 1303777 | H34: =C34/$B34 -> 0.31604248 | I34: =D34/$B34 -> 0.26587346 | J34: =E34/$B34 -> 0.22081549 | K34: =F34/$B34 -> 0.12633541 | L34: =G34/$B34 -> 0.067157868
A35: Apr | B35: 19309996 | C35: 6352087 | D35: 5086150 | E35: 4100993 | F35: 2392698 | G35: 0 | H35: =C35/$B35 -> 0.3289533 | I35: =D35/$B35 -> 0.26339467 | J35: =E35/$B35 -> 0.21237669 | K35: =F35/$B35 -> 0.12390981 | L35: =G35/$B35 -> 0 | N35: =B35-B36 -> 1065 | O35: =C35-C36 -> -10680
A36: Apr Exact Filters | B36: 19308931 | C36: 6362767
C38: =$G$33/C33 -> 0.20025836 | D38: =$G$33/D33 -> 0.24323397 | E38: =$G$33/E33 -> 0.29275575 | F38: =$G$33/F33 -> 0.50590061 | G38: =$G$33/G33 -> 1
C39: =$G$34/C34 -> 0.21249633 | D39: =$G$34/D34 -> 0.25259335 | E39: =$G$34/E34 -> 0.30413567 | F39: =$G$34/F34 -> 0.53158389 | G39: =$G$34/G34 -> 1
B41: Base | D41: Winback on 15th day | E41: 30th day
A42: Winback | B42: 19298361 | C42: 5967736 | D42: =C33-D33 -> 1054405 | E42: =D33-E33 -> 831126 | F42: =E33-F33 -> 1719905 | G42: =F33-G33 -> 1167211 | H42: =G33 -> 1195089
D43: =D42/$C$42 -> 0.17668426 | E43: =E42/$C$42 -> 0.1392699 | F43: =F42/$C$42 -> 0.28820058 | G43: =G42/$C$42 -> 0.1955869 | H43: =H42/$C$42 -> 0.20025836
D46: =D33/C33 -> 0.82331574 | E46: =E33/D33 -> 0.83084266 | F46: =F33/E33 -> 0.57868235 | G46: =G33/F33 -> 0.50590061

Sheet Segments
A1: Low | B1: Zero or LT Zero ARPU | C1: Low | F1: AON_SLAB | G1: (Multiple Items)
A2: Low | B2: 0 - 10 ARPU | C2: Low | F2: DATE | G2: (Multiple Items)
A3: Low | B3: 10 - 25 ARPU | C3: Low | N3: 1000000
A4: Medium | B4: 25 - 50 ARPU | C4: Medium | H4: Values
A5: Medium | B5: 50 - 75 ARPU | C5: Medium | F5: ARPU_Seg | G5: ARPU_SLAB_IND | H5: Sum of SEG_CNT | I5: Sum of AVGL3MREV | J5: Sum of ARPU | K5: Sum of SEG_CNT2 | L5: Sum of AVGL3MREV2 | N5: base | O5: rev | P5: arpu | Q5: base% | R5: rev%
A6: Medium | B6: 75 - 100 ARPU | C6: Medium | F6: Low | G6: Zero or LT Zero ARPU | H6: 94968 | I6: -661945.86 | J6: -6.970199 | K6: 0.0049210397 | L6: -0.0003795741 | N6: =(SUM(H6:H8))/1000000 -> 8.306794 | O6: =(SUM(I6:I8))/1000000 -> 62.337532 | P6: =SUM(J6:J8) -> 12.780717 | Q6: =SUM(K6:K8) -> 0.43044039 | R6: =SUM(L6:L8) -> 0.035745691
A7: Medium | B7: 100 - 125 ARPU | C7: Medium | F7: Low | G7: 0 - 10 ARPU | H7: 5417639 | I7: 16131838 | J7: 2.9776509 | K7: 0.28073052 | L7: 0.0092503452
A8: High | B8: 125 - 150 ARPU | C8: High | F8: Low | G8: 10 - 25 ARPU | H8: 2794187 | I8: 46867640 | J8: 16.773265 | K8: 0.14478882 | L8: 0.02687492
A9: High | B9: 150 - 200 ARPU | C9: High | F9: Medium | G9: 25 - 50 ARPU | H9: 2872645 | I9: 1.0484964e+08 | J9: 36.499337 | K9: 0.14885435 | L9: 0.060123053 | N9: =(SUM(H9:H12))/1000000 -> 6.964096 | O9: =(SUM(I9:I12))/1000000 -> 436.36261 | P9: =SUM(J9:J12) -> 296.83893 | Q9: =SUM(K9:K12) -> 0.36086464 | R9: =SUM(L9:L12) -> 0.25021977
A10: High | B10: 200 - 300 ARPU | C10: High | F10: Medium | G10: 50 - 75 ARPU | H10: 1869758 | I10: 1.1533123e+08 | J10: 61.682436 | K10: 0.096886881 | L10: 0.066133425
A11: VHigh | B11: 300 - 500 ARPU | C11: VHigh | F11: Medium | G11: 75 - 100 ARPU | H11: 1290283 | I11: 1.1199765e+08 | J11: 86.800839 | K11: 0.066859719 | L11: 0.064221877
A12: VHigh | B12: GT 500 | C12: VHigh | F12: Medium | G12: 100 - 125 ARPU | H12: 931410 | I12: 1.0418409e+08 | J12: 111.85632 | K12: 0.048263684 | L12: 0.059741417
F13: High | G13: 125 - 150 ARPU | H13: 698320 | I13: 95603472 | J13: 136.90496 | K13: 0.036185456 | L13: 0.054821102 | N13: =(SUM(H13:H15))/1000000 -> 2.691058 | O13: =(SUM(I13:I15))/1000000 -> 513.46075 | P13: =SUM(J13:J15) -> 553.51742 | Q13: =SUM(K13:K15) -> 0.1394449 | R13: =SUM(L13:L15) -> 0.29442952
F14: High | G14: 150 - 200 ARPU | H14: 957313 | I14: 1.6561877e+08 | J14: 173.00378 | K14: 0.049605922 | L14: 0.094969389
F15: High | G15: 200 - 300 ARPU | H15: 1035425 | I15: 2.5223852e+08 | J15: 243.60868 | K15: 0.05365352 | L15: 0.14463903
F16: VHigh | G16: 300 - 500 ARPU | H16: 802036 | I16: 3.0555183e+08 | J16: 380.97022 | K16: 0.041559799 | L16: 0.17521004 | N16: =(SUM(H16:H17))/1000000 -> 1.336413 | O16: =(SUM(I16:I17))/1000000 -> 731.75647 | P16: =SUM(J16:J17) -> 1178.5432 | Q16: =SUM(K16:K17) -> 0.069250078 | R16: =SUM(L16:L17) -> 0.41960501
F17: VHigh | G17: GT 500 | H17: 534377 | I17: 4.2620464e+08 | J17: 797.57294 | K17: 0.027690279 | L17: 0.24439497 | N17: =SUM(N6:N16) -> 19.298361 | O17: =SUM(O6:O16) -> 1743.9174 | P17: =SUM(P6:P16) -> 2041.6802 | Q17: =SUM(Q6:Q16) -> 1 | R17: =SUM(R6:R16) -> 1
F18: Grand Total | H18: 19298361 | I18: 1.7439174e+09 | J18: 90.366087 | K18: 1 | L18: 1
J23: =SUM(H9:H12) -> 6964096

Sheet Segments (2)
B1: AON_SLAB | C1: (Multiple Items)
B2: DATE | C2: (Multiple Items)
D4: Values | J4: ARPR>=90 | K4: =E18/D18 -> 90.366087
B5: ARPU_Seg | C5: ARPU_SLAB_IND | D5: Sum of SEG_CNT | E5: Sum of AVGL3MREV | F5: Sum of ARPU | G5: Sum of SEG_CNT2 | H5: Sum of AVGL3MREV2
B6: Low | C6: Zero or LT Zero ARPU | D6: 94968 | E6: -661945.86 | F6: -6.970199 | G6: 0.0049210397 | H6: -0.0003795741
B7: Low | C7: 0 - 10 ARPU | D7: 5417639 | E7: 16131838 | F7: 2.9776509 | G7: 0.28073052 | H7: 0.0092503452
B8: Low | C8: 10 - 25 ARPU | D8: 2794187 | E8: 46867640 | F8: 16.773265 | G8: 0.14478882 | H8: 0.02687492
B9: Medium | C9: 25 - 50 ARPU | D9: 2872645 | E9: 1.0484964e+08 | F9: 36.499337 | G9: 0.14885435 | H9: 0.060123053
B10: Medium | C10: 50 - 75 ARPU | D10: 1869758 | E10: 1.1533123e+08 | F10: 61.682436 | G10: 0.096886881 | H10: 0.066133425
B11: Medium | C11: 75 - 100 ARPU | D11: 1290283 | E11: 1.1199765e+08 | F11: 86.800839 | G11: 0.066859719 | H11: 0.064221877
B12: Medium | C12: 100 - 125 ARPU | D12: 931410 | E12: 1.0418409e+08 | F12: 111.85632 | G12: 0.048263684 | H12: 0.059741417
B13: High | C13: 125 - 150 ARPU | D13: 698320 | E13: 95603472 | F13: 136.90496 | G13: 0.036185456 | H13: 0.054821102
B14: High | C14: 150 - 200 ARPU | D14: 957313 | E14: 1.6561877e+08 | F14: 173.00378 | G14: 0.049605922 | H14: 0.094969389
B15: High | C15: 200 - 300 ARPU | D15: 1035425 | E15: 2.5223852e+08 | F15: 243.60868 | G15: 0.05365352 | H15: 0.14463903
B16: VHigh | C16: 300 - 500 ARPU | D16: 802036 | E16: 3.0555183e+08 | F16: 380.97022 | G16: 0.041559799 | H16: 0.17521004
B17: VHigh | C17: GT 500 | D17: 534377 | E17: 4.2620464e+08 | F17: 797.57294 | G17: 0.027690279 | H17: 0.24439497
B18: Grand Total | D18: 19298361 | E18: 1.7439174e+09 | F18: 90.366087 | G18: 1 | H18: 1
F23: =SUM(D9:D12) -> 6964096

Sheet ARPU_Segments
B1: AON_SLAB | C1: (Multiple Items)
B2: DATE | C2: (Multiple Items)
D4: Values
A5: Low | B5: ARPU_Seg | C5: ARPU_SLAB_IND | D5: Sum of SEG_CNT | E5: Sum of AVGL3MREV | F5: Sum of ARPU | G5: Sum of SEG_CNT2 | H5: Sum of AVGL3MREV2 | I5: Sum of CNT_DOLA_7INC | J5: Sum of CNT_DOLA_15INC | K5: Sum of CNT_DOLA_30INC | L5: Sum of CNT_DOLA_60INC | M5: Sum of CNT_DOLA_90INC | N5: DOLA>=7D% | O5: DOLA>=15D% | P5: DOLA>=30D% | Q5: DOLA>=60D% | R5: DOLA>=90D%
A6: Low | B6: Low | C6: Zero or LT Zero ARPU | D6: 94968 | E6: -661945.86 | F6: -6.970199 | G6: 0.0049210397 | H6: -0.0003795741 | I6: 38851 | J6: 34113 | K6: 27841 | L6: 16844 | M6: 11706 | N6: =I6/$D6 -> 0.4090957 | O6: =J6/$D6 -> 0.35920521 | P6: =K6/$D6 -> 0.29316191 | Q6: =L6/$D6 -> 0.17736501 | R6: =M6/$D6 -> 0.12326257
A7: Low | B7: Low | C7: 0 - 10 ARPU | D7: 5417639 | E7: 16131838 | F7: 2.9776509 | G7: 0.28073052 | H7: 0.0092503452 | I7: 3640978 | J7: 3093906 | K7: 2561278 | L7: 1334220 | M7: 678703 | N7: =I7/$D7 -> 0.67205991 | O7: =J7/$D7 -> 0.57108013 | P7: =K7/$D7 -> 0.47276646 | Q7: =L7/$D7 -> 0.24627333 | R7: =M7/$D7 -> 0.12527653
A8: Medium | B8: Low | C8: 10 - 25 ARPU | D8: 2794187 | E8: 46867640 | F8: 16.773265 | G8: 0.14478882 | H8: 0.02687492 | I8: 1078177 | J8: 852997 | K8: 715878 | L8: 439986 | M8: 211669 | N8: =I8/$D8 -> 0.3858643 | O8: =J8/$D8 -> 0.30527556 | P8: =K8/$D8 -> 0.25620261 | Q8: =L8/$D8 -> 0.15746477 | R8: =M8/$D8 -> 0.075753341
A9: Medium | B9: Medium | C9: 25 - 50 ARPU | D9: 2872645 | E9: 1.0484964e+08 | F9: 36.499337 | G9: 0.14885435 | H9: 0.060123053 | I9: 635035 | J9: 488684 | K9: 407531 | L9: 287408 | M9: 140676 | N9: =I9/$D9 -> 0.22106282 | O9: =J9/$D9 -> 0.17011639 | P9: =K9/$D9 -> 0.14186612 | Q9: =L9/$D9 -> 0.10004995 | R9: =M9/$D9 -> 0.048970896
A10: Medium | B10: Medium | C10: 50 - 75 ARPU | D10: 1869758 | E10: 1.1533123e+08 | F10: 61.682436 | G10: 0.096886881 | H10: 0.066133425 | I10: 251572 | J10: 192488 | K10: 160710 | L10: 120794 | M10: 61778
A11: Medium | B11: Medium | C11: 75 - 100 ARPU | D11: 1290283 | E11: 1.1199765e+08 | F11: 86.800839 | G11: 0.066859719 | H11: 0.064221877 | I11: 121543 | J11: 93576 | K11: 78038 | L11: 59994 | M11: 32020
A12: High | B12: Medium | C12: 100 - 125 ARPU | D12: 931410 | E12: 1.0418409e+08 | F12: 111.85632 | G12: 0.048263684 | H12: 0.059741417 | I12: 65998 | J12: 51037 | K12: 42475 | L12: 33004 | M12: 18162
A13: High | B13: High | C13: 125 - 150 ARPU | D13: 698320 | E13: 95603472 | F13: 136.90496 | G13: 0.036185456 | H13: 0.054821102 | I13: 39886 | J13: 31077 | K13: 25819 | L13: 20239 | M13: 11316
A14: High | B14: High | C14: 150 - 200 ARPU | D14: 957313 | E14: 1.6561877e+08 | F14: 173.00378 | G14: 0.049605922 | H14: 0.094969389 | I14: 42890 | J14: 33490 | K14: 27854 | L14: 21912 | M14: 12494
A15: VHigh | B15: High | C15: 200 - 300 ARPU | D15: 1035425 | E15: 2.5223852e+08 | F15: 243.60868 | G15: 0.05365352 | H15: 0.14463903 | I15: 31727 | J15: 25104 | K15: 20874 | L15: 16646 | M15: 9616
A16: VHigh | B16: VHigh | C16: 300 - 500 ARPU | D16: 802036 | E16: 3.0555183e+08 | F16: 380.97022 | G16: 0.041559799 | H16: 0.17521004 | I16: 15366 | J16: 12308 | K16: 10197 | L16: 8240 | M16: 5010
B17: VHigh | C17: GT 500 | D17: 534377 | E17: 4.2620464e+08 | F17: 797.57294 | G17: 0.027690279 | H17: 0.24439497 | I17: 5713 | J17: 4551 | K17: 3710 | L17: 3013 | M17: 1939
B18: Grand Total | D18: 19298361 | E18: 1.7439174e+09 | F18: 90.366087 | G18: 1 | H18: 1 | I18: 5967736 | J18: 4913331 | K18: 4082205 | L18: 2362300 | M18: 1195089
L24: Old for comparison
B25: SAURAV_OLD_for comparison | C25: Sum of Sum of SEG_CNT | D25: Sum of SEG_CNT | E25: Sum of Sum of AVGL3MREV | F25: Sum of AVGL3MREV | L25: Segment | M25: ARPU(L3M) | N25: Base (MN) | O25: Base% | P25: Revenue(L3M)(MN) | Q25: Value loss(MN) | R25: Value loss% | S25: 7D_Inactivity% | T25: 15D_Inactivity% | U25: 30D_Inactivity% | V25: Churn% (90 day)
B26: Low | C26: 8306785 | D26: 0.43044006 | E26: 62337532 | F26: 0.035745626 | L26: Low | M26: 7.5 | N26: 8.3 | O26: 0.43 | P26: 62.3 | Q26: 6.8 | R26: 0.207 | S26: 0.573 | T26: 0.479 | U26: 0.398 | V26: 0.109
B27: Medium | C27: 6964093 | D27: 0.36086459 | E27: 4.363626e+08 | F27: 0.25021932 | L27: Medium | M27: 62.7 | N27: 7 | O27: 0.361 | P27: 436.4 | Q27: 15.8 | R27: 0.483 | S27: 0.154 | T27: 0.119 | U27: 0.099 | V27: 0.036
B28: High | C28: 2691062 | D28: 0.13944515 | E28: 5.1346185e+08 | F28: 0.29442961 | L28: High | M28: 190.8 | N28: 2.7 | O28: 0.139 | P28: 513.5 | Q28: 6.4 | R28: 0.195 | S28: 0.043 | T28: 0.033 | U28: 0.028 | V28: 0.012
B29: VHigh | C29: 1336415 | D29: 0.069250203 | E29: 7.3175855e+08 | F29: 0.41960544 | L29: VHigh | M29: 547.6 | N29: 1.3 | O29: 0.069 | P29: 731.8 | Q29: 3.8 | R29: 0.116 | S29: 0.016 | T29: 0.013 | U29: 0.01 | V29: 0.005
B30: Grand Total | C30: 19298355 | D30: 1 | E30: 1.7439205e+09 | F30: 1

Sheet Value_Loss
B1: AON_SLAB | C1: (Multiple Items)
B2: DATE | C2: (Multiple Items)
B3: ARPU_SLAB_IND | C3: (All) | H3: =$L$7/H7 -> 0.23519664 | I3: =$L$7/I7 -> 0.30593435 | J3: =$L$7/J7 -> 0.3668015 | K3: =$L$7/K7 -> 0.50406225 | L3: =$L$7/L7 -> 1
B5: Row Labels | C5: Sum of SEG_CNT | D5: Sum of AVGL3MREV | E5: Sum of SEG_CNT2 | F5: Sum of AVGL3MREV2 | G5: Sum of ARPU | H5: Sum of CNT_DOLA_7INC | I5: Sum of CNT_DOLA_15INC | J5: Sum of CNT_DOLA_30INC | K5: Sum of CNT_DOLA_60INC | L5: Sum of CNT_DOLA_90INC | M5: Sum of 7DI% | N5: Sum of 15DI% | O5: Sum of 30DI% | P5: Sum of 60DI% | Q5: Sum of 90DI%
B6: Low | C6: 8306794 | D6: 62337532 | E6: 0.43044039 | F6: 0.035745691 | G6: 7.5044032 | H6: 4758006 | I6: 3981016 | J6: 3304997 | K6: 1791050 | L6: 902078 | M6: 0.57278488 | N6: 0.47924819 | O6: 0.39786673 | P6: 0.21561267 | Q6: 0.10859521
B7: Medium | C7: 6964096 | D7: 4.3636261e+08 | E7: 0.36086464 | F7: 0.25021977 | G7: 62.658901 | H7: 1074148 | I7: 825785 | J7: 688754 | K7: 501200 | L7: 252636 | M7: 0.15424084 | N7: 0.11857749 | O7: 0.098900704 | P7: 0.07196914 | Q7: 0.036276927
B8: High | C8: 2691058 | D8: 5.1346075e+08 | E8: 0.1394449 | F8: 0.29442952 | G8: 190.80256 | H8: 114503 | I8: 89671 | J8: 74547 | K8: 58797 | L8: 33426 | M8: 0.042549436 | N8: 0.033321838 | O8: 0.027701744 | P8: 0.021849027 | Q8: 0.012421137
B9: VHigh | C9: 1336413 | D9: 7.3175647e+08 | E9: 0.069250078 | F9: 0.41960501 | G9: 547.55264 | H9: 21079 | I9: 16859 | J9: 13907 | K9: 11253 | L9: 6949 | M9: 0.015772819 | N9: 0.012615112 | O9: 0.010406214 | P9: 0.0084203012 | Q9: 0.0051997399
B10: Grand Total | C10: 19298361 | D10: 1.7439174e+09 | E10: 1 | F10: 1 | G10: 90.366087 | H10: 5967736 | I10: 4913331 | J10: 4082205 | K10: 2362300 | L10: 1195089 | M10: 0.30923538 | N10: 0.25459836 | O10: 0.21153118 | P10: 0.12240936 | Q10: 0.061926969
C12: 7709549 | M12: 0.15424084 | N12: 0.11857749 | O12: 0.098900704 | P12: 0.07196914 | Q12: 0.036276927
B13: SORB | C13: 6912010 | I13: =H7-I7 -> 248363 | J13: =H7-J7 -> 385394 | K13: =J7-K7 -> 187554 | L13: =K7-L7 -> 248564
C14: 2992769
C15: 1684033
C16: 19298361
D17: AON>=90
D18: Segment | E18: ARPU(L3M) | F18: Churn (90 day) | G18: Base | H18: Rev(L3M) in Million | I18: Value loss | J18: Value loss% | K18: Base% | L18: 7dy_inactivity | M18: 15dy_inactivity | N18: 30dy_inactivity | O18: Revenue | P18: =SUM(H19:H22) -> 1.7439174e+09
D19: Low | E19: 7.5044032 | F19: 0.10859521 | G19: 8306794 | H19: 62337532 | I19: =+F19*E19*G19 -> 6769557 | J19: =+I19/SUM($I$19:$I$22) -> 0.20650124 | K19: =+G19/SUM($G$19:$G$22) -> 0.43044039 | L19: 0.57278488 | M19: 0.47924819 | N19: 0.39786673 | O19: Value Loss | P19: =SUM(I19:I22) -> 32782161
D20: Medium | E20: 62.658901 | F20: 0.036276927 | G20: 6964096 | H20: 4.3636261e+08 | I20: =+F20*E20*G20 -> 15829894 | J20: =+I20/SUM($I$19:$I$22) -> 0.48288135 | K20: =+G20/SUM($G$19:$G$22) -> 0.36086464 | L20: 0.15424084 | M20: 0.11857749 | N20: 0.098900704 | O20: Value Churn | P20: =P19/P18 -> 0.018798001
D21: High | E21: 190.80256 | F21: 0.012421137 | G21: 2691058 | H21: 5.1346075e+08 | I21: =+F21*E21*G21 -> 6377766.4 | J21: =+I21/SUM($I$19:$I$22) -> 0.19454991 | K21: =+G21/SUM($G$19:$G$22) -> 0.1394449 | L21: 0.042549436 | M21: 0.033321838 | N21: 0.027701744
D22: VHigh | E22: 547.55264 | F22: 0.0051997399 | G22: 1336413 | H22: 7.3175647e+08 | I22: =+F22*E22*G22 -> 3804943.3 | J22: =+I22/SUM($I$19:$I$22) -> 0.1160675 | K22: =+G22/SUM($G$19:$G$22) -> 0.069250078 | L22: 0.015772819 | M22: 0.012615112 | N22: 0.010406214
D24: AON<90
D25: Segment | E25: ARPU(L3M) | F25: Churn (90 day) | G25: Base | H25: Rev(L3M) in Million | I25: Value loss | J25: Value loss% | K25: Base% | L25: 7dy_inactivity | M25: 15dy_inactivity | N25: 30dy_inactivity | O25: Revenue | P25: =SUM(H26:H29) -> 1.1027228e+08
D26: Low | E26: 5.4375282 | F26: 0.22020903 | G26: 4603476 | H26: 25031531 | I26: =+F26*E26*G26 -> 5512169.2 | J26: =+I26/SUM($I$19:$I$22) -> 0.16814539 | K26: =+G26/SUM($G$19:$G$22) -> 0.23854233 | L26: 0.66450591 | M26: 0.60594103 | N26: 0.56282513 | O26: Value Loss | P26: =SUM(I26:I29) -> 11983610
D27: Medium | E27: 52.807764 | F27: 0.092599555 | G27: 949497 | H27: 50140813 | I27: =+F27*E27*G27 -> 4643017 | J27: =+I27/SUM($I$19:$I$22) -> 0.14163243 | K27: =+G27/SUM($G$19:$G$22) -> 0.049200914 | L27: 0.25242523 | M27: 0.2151655 | N27: 0.1932697 | O27: Value Churn | P27: =P26/P25 -> 0.10867292
D28: High | E28: 179.84716 | F28: 0.058142518 | G28: 120841 | H28: 21732910 | I28: =+F28*E28*G28 -> 1263606.1 | J28: =+I28/SUM($I$19:$I$22) -> 0.038545541 | K28: =+G28/SUM($G$19:$G$22) -> 0.0062617235 | L28: 0.13920772 | M28: 0.12350113 | N28: 0.11224667
D29: VHigh | E29: 501.61451 | F29: 0.042254578 | G29: 26648 | H29: 13367023 | I29: =+F29*E29*G29 -> 564817.94 | J29: =+I29/SUM($I$19:$I$22) -> 0.01722943 | K29: =+G29/SUM($G$19:$G$22) -> 0.0013808427 | L29: 0.092427199 | M29: 0.084096367 | N29: 0.076516061
D35: OLD_ AON > 90 for comparison
D36: Segment | E36: ARPU(L3M) | F36: Base (MN) | G36: Base% | H36: Revenue(L3M)(MN) | I36: Value loss(MN) | J36: Value loss% | K36: 7D_Inactivity% | L36: 15D_Inactivity% | M36: 30D_Inactivity% | N36: Churn% (90 day)
D37: Low | E37: 7.5 | F37: 8.3 | G37: 0.43 | H37: 62.3 | I37: 6.8 | J37: 0.207 | K37: 0.573 | L37: 0.479 | M37: 0.398 | N37: 0.109
D38: Medium | E38: 62.7 | F38: 7 | G38: 0.361 | H38: 436.4 | I38: 15.8 | J38: 0.483 | K38: 0.154 | L38: 0.119 | M38: 0.099 | N38: 0.036
D39: High | E39: 190.8 | F39: 2.7 | G39: 0.139 | H39: 513.5 | I39: 6.4 | J39: 0.195 | K39: 0.043 | L39: 0.033 | M39: 0.028 | N39: 0.012
D40: VHigh | E40: 547.6 | F40: 1.3 | G40: 0.069 | H40: 731.8 | I40: 3.8 | J40: 0.116 | K40: 0.016 | L40: 0.013 | M40: 0.01 | N40: 0.005

Sheet Sheet8
B2: base | C2: churn | D2: churn% | E2: Rev | F2: ARPU
B3: 50 | C3: 5 | D3: =C3/B3 -> 0.1 | E3: 100 | F3: =E3/B3 -> 2 | G3: =F3*D3*B3 -> 10
A5: high | B5: 30 | C5: 5 | D5: =C5/B5 -> 0.16666667 | E5: 50 | F5: =E5/B5 -> 1.6666667 | G5: =F5*D5*B5 -> 8.3333333
A6: med | B6: 10 | C6: 5 | D6: =C6/B6 -> 0.5 | E6: 30 | F6: =E6/B6 -> 3 | G6: =F6*D6*B6 -> 15
A7: low | B7: 10 | C7: 5 | D7: =C7/B7 -> 0.5 | E7: 20 | F7: =E7/B7 -> 2 | G7: =F7*D7*B7 -> 10

Sheet Value_Loss_Med
B1: AON_SLAB | C1: (Multiple Items)
B2: ARPU_Seg | C2: Medium
B3: DATE | C3: (Multiple Items) | H3: =$L$7/H7 -> 0.24556787 | I3: =$L$7/I7 -> 0.32094468 | J3: =$L$7/J7 -> 0.3844067 | K3: =$L$7/K7 -> 0.51143269 | L3: =$L$7/L7 -> 1
B5: Row Labels | C5: Sum of SEG_CNT | D5: Sum of AVGL3MREV | E5: Sum of SEG_CNT2 | F5: Sum of AVGL3MREV2 | G5: Sum of ARPU | H5: Sum of CNT_DOLA_7INC | I5: Sum of CNT_DOLA_15INC | J5: Sum of CNT_DOLA_30INC | K5: Sum of CNT_DOLA_60INC | L5: Sum of CNT_DOLA_90INC | M5: Sum of 7DI% | N5: Sum of 15DI% | O5: Sum of 30DI% | P5: Sum of 60DI% | Q5: Sum of 90DI%
B6: 25 - 50 ARPU | C6: 2872645 | D6: 1.0484964e+08 | E6: 0.4124936 | F6: 0.24028098 | G6: 36.499337 | H6: 635035 | I6: 488684 | J6: 407531 | K6: 287408 | L6: 140676 | M6: 0.22106282 | N6: 0.17011639 | O6: 0.14186612 | P6: 0.10004995 | Q6: 0.048970896
B7: 50 - 75 ARPU | C7: 1869758 | D7: 1.1533123e+08 | E7: 0.26848539 | F7: 0.26430135 | G7: 61.682436 | H7: 251572 | I7: 192488 | J7: 160710 | K7: 120794 | L7: 61778 | M7: 0.13454789 | N7: 0.10294808 | O7: 0.0859523 | P7: 0.064604082 | Q7: 0.033040639
B8: 75 - 100 ARPU | C8: 1290283 | D8: 1.1199765e+08 | E8: 0.18527645 | F8: 0.25666188 | G8: 86.800839 | H8: 121543 | I8: 93576 | J8: 78038 | K8: 59994 | L8: 32020 | M8: 0.094198715 | N8: 0.072523625 | O8: 0.060481305 | P8: 0.046496776 | Q8: 0.024816261
B9: 100 - 125 ARPU | C9: 931410 | D9: 1.0418409e+08 | E9: 0.13374457 | F9: 0.23875578 | G9: 111.85632 | H9: 65998 | I9: 51037 | J9: 42475 | K9: 33004 | L9: 18162 | M9: 0.070858161 | N9: 0.054795418 | O9: 0.045602903 | P9: 0.035434449 | Q9: 0.019499469
